Workbook

Sheet Executive Summary
A1: Final QA — Authoritative Signature-Management Event Database
A2: Reconciliation cut-off: 9 Sep 2026 | Land-platform core; contextual evidence retained separately.
A4: Conclusion unchanged but better qualified: evidence supports a broader and awakening activity base, while order counts remain uneven and materially concentrated in ULCANS and Japan MEDS.
A6: Metric | B6: Final QA
A7: Retained lifecycle events | B7: =COUNTA('Master Events'!$A$5:$A$147)
A8: Land-core events | B8: =COUNTIF('Master Events'!$AC$5:$AC$147,"Yes")
A9: Contextual events | B9: =B7-B8
A10: Land-core Actual Orders | B10: =COUNTIFS('Master Events'!$AC$5:$AC$147,"Yes",'Master Events'!$R$5:$R$147,"Yes")
A11: Land-core programme families | B11: =SUM('Master Events'!$AV$5:$AV$147)
A12: All retained programme families | B12: 45
A15: Year | B15: Actual Orders | C15: Active Families | D15: Largest Family | E15: Largest Family Orders | F15: Largest Share | G15: ULCANS Orders | H15: Japan MEDS Orders
A16: 2020 | B16: 14 | C16: 4 | D16: ULCANS-IDV-W911QY18D0210 | E16: 13 | F16: 0.92857143 | G16: 13 | H16: 0
A17: 2021 | B17: 5 | C17: 3 | D17: ULCANS-IDV-W911QY18D0210 | E17: 4 | F17: 0.8 | G17: 4 | H17: 0
A18: 2022 | B18: 6 | C18: 5 | D18: ULCANS-IDV-W911QY18D0210 | E18: 4 | F18: 0.66666667 | G18: 4 | H18: 0
A19: 2023 | B19: 5 | C19: 5 | D19: NO-SAAB-MCS-4600002386 | E19: 2 | F19: 0.4 | G19: 2 | H19: 0
A20: 2024 | B20: 13 | C20: 13 | D20: ULCANS-IDV-W911QY18D0210 | E20: 3 | F20: 0.23076923 | G20: 3 | H20: 1
A21: 2025 | B21: 18 | C21: 9 | D21: JP-MEDS | E21: 13 | F21: 0.72222222 | G21: 3 | H21: 13
A22: 2026 | B22: 15 | C22: 14 | D22: JP-MEDS | E22: 4 | F22: 0.26666667 | G22: 4 | H22: 4

Sheet Master Events
A1: Final Authoritative Master Event Table — QA Passed
A2: 143 retained lifecycle events; 115 land-core events; 76 land-core Actual Orders. Final QA cut-off: 9 Sep 2026.
A4: Event ID | B4: Programme / Procurement Family ID | C4: Date | D4: Year | E4: Country | F4: Buyer / Contracting Authority | G4: Canonical Buyer | H4: Military Branch | I4: Supplier | J4: Canonical Supplier | K4: Supplier Country | L4: Programme / Requirement | M4: Platform | N4: Product / Solution | O4: Signature Domain | P4: Event Type | Q4: Procurement Stage | R4: Actual Order? | S4: Quantity | T4: Quantity Unit | U4: Quantity Basis | V4: Monetary Value | W4: Currency | X4: Value Basis | Y4: Framework / Ceiling / Obligated distinction | Z4: Repeat / Follow-on? | AA4: Production vs Development / Validation | AB4: Operating Domain | AC4: Core Metric Inclusion? | AD4: Exclusion Reason | AE4: Source URL | AF4: Source Type | AG4: Evidence Quality | AH4: Confidence | AI4: Notes / Caveats | AJ4: Existing in company-based? | AK4: Existing in event-based? | AL4: Existing only in company-master enrichment? | AM4: Newly discovered? | AN4: Duplicate of existing event? | AO4: Same programme family as another event? | AP4: Inclusion decision | AQ4: First family-year flag | AR4: First ordered-family-year flag | AS4: First supplier-year flag | AT4: First buyer-year flag | AU4: First country-year flag | AV4: Programme first observed flag | AW4: Repeat-order / call-off flag
A5: SM-0001 | B5: ULCANS-IDV-W911QY18D0210 | C5: 2020-02-07 | D5: 2020 | E5: United States | F5: ACC Aberdeen Proving Ground (Natick) / PEO CS&CSS, U.S. Army | G5: U.S. Army | H5: Army / Land | I5: Fibrotex USA Inc. / Fibrotex Technologies | J5: Fibrotex | K5: Israel / USA | L5: W911QY20F0114 — ULCANS delivery order under W911QY18D0210 | M5: Nets / Covers | N5: Ultra-Lightweight Camouflage Net System (ULCANS) | O5: Multispectral | P5: Order | R5: Yes | T5: Unknown | V5: 72600.0 | W5: USD | Y5: Obligated / signed if disclosed | Z5: No | AA5: Production Procurement | AB5: Land | AC5: Yes | AE5: https://www.federalcompass.com/fed-contract-award/W911QY18D0210 | AF5: Other credible third-party source (FPDS-derived task-order history) | AG5: Secondary / aggregator | AH5: Medium | AI5: Distinct committed delivery order W911QY20F0114 shown in the cited task-order history. Parent IDIQ ceiling is not counted as sales. | AJ5: Yes | AK5: No | AL5: No | AM5: No | AN5: No | AO5: Yes | AP5: Included in Land core | AQ5: 1 | AR5: 1 | AS5: 1 | AT5: 1 | AU5: 1 | AV5: 1 | AW5: 0
A6: SM-0002 | B6: AMET-MESH-2020 | C6: 2020-02-15 | D6: 2020 | E6: United States | F6: Naval Research Laboratory / ONR | G6: U.S. NRL / ONR | H6: Navy | I6: Ametrine Technologies | J6: Ametrine Technologies | K6: USA | L6: N0017320P0084 | M6: Expeditionary/static | N6: Multispectral mesh | O6: Multispectral | P6: Funded prototype procurement | Q6: Completion | R6: No | T6: Unknown | U6: Unknown | V6: 168800 | W6: USD | X6: Reported award value | Y6: Obligated / signed if disclosed | Z6: No | AA6: Development / Validation | AB6: Other / Contextual | AC6: No | AD6: End use / platform not publicly established; NRL/ONR buyer alone does not establish maritime or land domain | AE6: https://www.federalcompass.com/fed-contract-award/N0017320P0084 | AF6: Federal award database mirror | AG6: Supplier / prime announcement | AH6: Medium | AI6: NRL/ONR context; treated as development, not production procurement. | AJ6: No | AK6: Yes | AL6: No | AM6: No | AN6: No | AO6: No | AP6: Retained as contextual; excluded from Land core | AQ6: 0 | AR6: 0 | AS6: 0 | AT6: 0 | AU6: 0 | AV6: 0 | AW6: 0
A7: SM-0003 | B7: ULCANS-IDV-W911QY18D0210 | C7: 2020-03-27 | D7: 2020 | E7: United States | F7: ACC Aberdeen Proving Ground (Natick) / PEO CS&CSS, U.S. Army | G7: U.S. Army | H7: Army / Land | I7: Fibrotex USA Inc. / Fibrotex Technologies | J7: Fibrotex | K7: Israel / USA | L7: W911QY20F0174 — ULCANS delivery order under W911QY18D0210 | M7: Nets / Covers | N7: Ultra-Lightweight Camouflage Net System (ULCANS) | O7: Multispectral | P7: Order | R7: Yes | T7: Unknown | V7: 5000000.0 | W7: USD | Y7: Obligated / signed if disclosed | Z7: Yes | AA7: Production Procurement | AB7: Land | AC7: Yes | AE7: https://www.federalcompass.com/fed-contract-award/W911QY18D0210 | AF7: Other credible third-party source (FPDS-derived task-order history) | AG7: Secondary / aggregator | AH7: Medium | AI7: Distinct committed delivery order W911QY20F0174 shown in the cited task-order history. Parent IDIQ ceiling is not counted as sales. | AJ7: Yes | AK7: Yes | AL7: No | AM7: No | AN7: No | AO7: Yes | AP7: Included in Land core | AQ7: 0 | AR7: 0 | AS7: 0 | AT7: 0 | AU7: 0 | AV7: 0 | AW7: 1
A8: SM-0004 | B8: ULCANS-IDV-W911QY18D0210 | C8: 2020-03-27 | D8: 2020 | E8: United States | F8: ACC Aberdeen Proving Ground (Natick) / PEO CS&CSS, U.S. Army | G8: U.S. Army | H8: Army / Land | I8: Fibrotex USA Inc. / Fibrotex Technologies | J8: Fibrotex | K8: Israel / USA | L8: W911QY20F0175 — ULCANS delivery order under W911QY18D0210 | M8: Nets / Covers | N8: Ultra-Lightweight Camouflage Net System (ULCANS) | O8: Multispectral | P8: Order | R8: Yes | T8: Unknown | V8: 19900000.0 | W8: USD | Y8: Obligated / signed if disclosed | Z8: Yes | AA8: Production Procurement | AB8: Land | AC8: Yes | AE8: https://www.federalcompass.com/fed-contract-award/W911QY18D0210 | AF8: Other credible third-party source (FPDS-derived task-order history) | AG8: Secondary / aggregator | AH8: Medium | AI8: Distinct committed delivery order W911QY20F0175 shown in the cited task-order history. Parent IDIQ ceiling is not counted as sales. | AJ8: Yes | AK8: No | AL8: No | AM8: No | AN8: No | AO8: Yes | AP8: Included in Land core | AQ8: 0 | AR8: 0 | AS8: 0 | AT8: 0 | AU8: 0 | AV8: 0 | AW8: 1
A9: SM-0005 | B9: ULCANS-IDV-W911QY18D0210 | C9: 2020-06-09 | D9: 2020 | E9: United States | F9: ACC Aberdeen Proving Ground (Natick) / PEO CS&CSS, U.S. Army | G9: U.S. Army | H9: Army / Land | I9: Fibrotex USA Inc. / Fibrotex Technologies | J9: Fibrotex | K9: Israel / USA | L9: W911QY20F0273 — ULCANS delivery order under W911QY18D0210 | M9: Nets / Covers | N9: Ultra-Lightweight Camouflage Net System (ULCANS) | O9: Multispectral | P9: Order | R9: Yes | T9: Unknown | V9: 52500.0 | W9: USD | Y9: Obligated / signed if disclosed | Z9: Yes | AA9: Production Procurement | AB9: Land | AC9: Yes | AE9: https://www.federalcompass.com/fed-contract-award/W911QY18D0210 | AF9: Other credible third-party source (FPDS-derived task-order history) | AG9: Secondary / aggregator | AH9: Medium | AI9: Distinct committed delivery order W911QY20F0273 shown in the cited task-order history. Parent IDIQ ceiling is not counted as sales. | AJ9: Yes | AK9: No | AL9: No | AM9: No | AN9: No | AO9: Yes | AP9: Included in Land core | AQ9: 0 | AR9: 0 | AS9: 0 | AT9: 0 | AU9: 0 | AV9: 0 | AW9: 1
A10: SM-0006 | B10: ULCANS-IDV-W911QY18D0210 | C10: 2020-09-09 | D10: 2020 | E10: United States | F10: ACC Aberdeen Proving Ground (Natick) / PEO CS&CSS, U.S. Army | G10: U.S. Army | H10: Army / Land | I10: Fibrotex USA Inc. / Fibrotex Technologies | J10: Fibrotex | K10: Israel / USA | L10: W911QY20F0463 — ULCANS delivery order under W911QY18D0210 | M10: Nets / Covers | N10: Ultra-Lightweight Camouflage Net System (ULCANS) | O10: Multispectral | P10: Order | R10: Yes | T10: Unknown | V10: 568400.0 | W10: USD | Y10: Obligated / signed if disclosed | Z10: Yes | AA10: Production Procurement | AB10: Land | AC10: Yes | AE10: https://www.federalcompass.com/fed-contract-award/W911QY18D0210 | AF10: Other credible third-party source (FPDS-derived task-order history) | AG10: Secondary / aggregator | AH10: Medium | AI10: Distinct committed delivery order W911QY20F0463 shown in the cited task-order history. Parent IDIQ ceiling is not counted as sales. | AJ10: Yes | AK10: No | AL10: No | AM10: No | AN10: No | AO10: Yes | AP10: Included in Land core | AQ10: 0 | AR10: 0 | AS10: 0 | AT10: 0 | AU10: 0 | AV10: 0 | AW10: 1
A11: SM-0007 | B11: ULCANS-IDV-W911QY18D0210 | C11: 2020-09-11 | D11: 2020 | E11: United States | F11: ACC Aberdeen Proving Ground (Natick) / PEO CS&CSS, U.S. Army | G11: U.S. Army | H11: Army / Land | I11: Fibrotex USA Inc. / Fibrotex Technologies | J11: Fibrotex | K11: Israel / USA | L11: W911QY20F0459 — ULCANS delivery order under W911QY18D0210 | M11: Nets / Covers | N11: Ultra-Lightweight Camouflage Net System (ULCANS) | O11: Multispectral | P11: Order | R11: Yes | T11: Unknown | V11: 1200000.0 | W11: USD | Y11: Obligated / signed if disclosed | Z11: Yes | AA11: Production Procurement | AB11: Land | AC11: Yes | AE11: https://www.federalcompass.com/fed-contract-award/W911QY18D0210 | AF11: Other credible third-party source (FPDS-derived task-order history) | AG11: Secondary / aggregator | AH11: Medium | AI11: Distinct committed delivery order W911QY20F0459 shown in the cited task-order history. Parent IDIQ ceiling is not counted as sales. | AJ11: Yes | AK11: No | AL11: No | AM11: No | AN11: No | AO11: Yes | AP11: Included in Land core | AQ11: 0 | AR11: 0 | AS11: 0 | AT11: 0 | AU11: 0 | AV11: 0 | AW11: 1
A12: SM-0008 | B12: SE-FMV-MSN-2020 | C12: 2020-09-14 | D12: 2020 | E12: Sweden | F12: Swedish Defence Materiel Administration (FMV) | G12: Swedish FMV | H12: Army / Land | I12: Saab Barracuda AB | J12: Saab Barracuda | K12: Sweden | L12: UH-2020-256 — Multispektrala Maskeringsnät | M12: Static / mobile land camouflage | N12: Multispectral camouflage nets | O12: Multispectral | P12: Tender | Q12: Tender | R12: No | T12: Unknown | U12: Tender range 2,000–4,000; not purchased quantity | X12: Tender stage | Y12: Obligated / signed if disclosed | Z12: No | AA12: Demand | AB12: Land | AC12: Yes | AE12: https://se.openprocurements.com/tender/2020-multispektrala-maskeringsnat/ | AF12: Official government / procurement record | AG12: Primary / official | AH12: High | AI12: Formal procurement notice. Option range is not counted as an order or delivered quantity. | AJ12: No | AK12: No | AL12: No | AM12: Yes | AN12: No | AO12: Yes | AP12: Included in Land core | AQ12: 1 | AR12: 0 | AS12: 1 | AT12: 1 | AU12: 1 | AV12: 1 | AW12: 0
A13: SM-0009 | B13: ULCANS-IDV-W911QY18D0210 | C13: 2020-09-18 | D13: 2020 | E13: United States | F13: ACC Aberdeen Proving Ground (Natick) / PEO CS&CSS, U.S. Army | G13: U.S. Army | H13: Army / Land | I13: Fibrotex USA Inc. / Fibrotex Technologies | J13: Fibrotex | K13: Israel / USA | L13: W911QY20F0514 — ULCANS delivery order under W911QY18D0210 | M13: Nets / Covers | N13: Ultra-Lightweight Camouflage Net System (ULCANS) | O13: Multispectral | P13: Order | R13: Yes | T13: Unknown | V13: 54600.0 | W13: USD | Y13: Obligated / signed if disclosed | Z13: Yes | AA13: Production Procurement | AB13: Land | AC13: Yes | AE13: https://www.federalcompass.com/fed-contract-award/W911QY18D0210 | AF13: Other credible third-party source (FPDS-derived task-order history) | AG13: Secondary / aggregator | AH13: Medium | AI13: Distinct committed delivery order W911QY20F0514 shown in the cited task-order history. Parent IDIQ ceiling is not counted as sales. | AJ13: Yes | AK13: Yes | AL13: No | AM13: No | AN13: No | AO13: Yes | AP13: Included in Land core | AQ13: 0 | AR13: 0 | AS13: 0 | AT13: 0 | AU13: 0 | AV13: 0 | AW13: 1
A14: SM-0010 | B14: ULCANS-IDV-W911QY18D0210 | C14: 2020-09-18 | D14: 2020 | E14: United States | F14: ACC Aberdeen Proving Ground (Natick) / PEO CS&CSS, U.S. Army | G14: U.S. Army | H14: Army / Land | I14: Fibrotex USA Inc. / Fibrotex Technologies | J14: Fibrotex | K14: Israel / USA | L14: W911QY20F0510 — ULCANS delivery order under W911QY18D0210 | M14: Nets / Covers | N14: Ultra-Lightweight Camouflage Net System (ULCANS) | O14: Multispectral | P14: Order | R14: Yes | T14: Unknown | V14: 140800.0 | W14: USD | Y14: Obligated / signed if disclosed | Z14: Yes | AA14: Production Procurement | AB14: Land | AC14: Yes | AE14: https://www.federalcompass.com/fed-contract-award/W911QY18D0210 | AF14: Other credible third-party source (FPDS-derived task-order history) | AG14: Secondary / aggregator | AH14: Medium | AI14: Distinct committed delivery order W911QY20F0510 shown in the cited task-order history. Parent IDIQ ceiling is not counted as sales. | AJ14: Yes | AK14: No | AL14: No | AM14: No | AN14: No | AO14: Yes | AP14: Included in Land core | AQ14: 0 | AR14: 0 | AS14: 0 | AT14: 0 | AU14: 0 | AV14: 0 | AW14: 1
A15: SM-0011 | B15: ULCANS-IDV-W911QY18D0210 | C15: 2020-09-25 | D15: 2020 | E15: United States | F15: ACC Aberdeen Proving Ground (Natick) / PEO CS&CSS, U.S. Army | G15: U.S. Army | H15: Army / Land | I15: Fibrotex USA Inc. / Fibrotex Technologies | J15: Fibrotex | K15: Israel / USA | L15: W911QY20F0521 — ULCANS delivery order under W911QY18D0210 | M15: Nets / Covers | N15: Ultra-Lightweight Camouflage Net System (ULCANS) | O15: Multispectral | P15: Order | R15: Yes | T15: Unknown | V15: 100000.0 | W15: USD | Y15: Obligated / signed if disclosed | Z15: Yes | AA15: Production Procurement | AB15: Land | AC15: Yes | AE15: https://www.federalcompass.com/fed-contract-award/W911QY18D0210 | AF15: Other credible third-party source (FPDS-derived task-order history) | AG15: Secondary / aggregator | AH15: Medium | AI15: Distinct committed delivery order W911QY20F0521 shown in the cited task-order history. Parent IDIQ ceiling is not counted as sales. | AJ15: Yes | AK15: No | AL15: No | AM15: No | AN15: No | AO15: Yes | AP15: Included in Land core | AQ15: 0 | AR15: 0 | AS15: 0 | AT15: 0 | AU15: 0 | AV15: 0 | AW15: 1
A16: SM-0012 | B16: ULCANS-IDV-W911QY18D0210 | C16: 2020-09-29 | D16: 2020 | E16: United States | F16: ACC Aberdeen Proving Ground (Natick) / PEO CS&CSS, U.S. Army | G16: U.S. Army | H16: Army / Land | I16: Fibrotex USA Inc. / Fibrotex Technologies | J16: Fibrotex | K16: Israel / USA | L16: W911QY20F0568 — ULCANS delivery order under W911QY18D0210 | M16: Nets / Covers | N16: Ultra-Lightweight Camouflage Net System (ULCANS) | O16: Multispectral | P16: Order | R16: Yes | T16: Unknown | V16: 32900.0 | W16: USD | Y16: Obligated / signed if disclosed | Z16: Yes | AA16: Production Procurement | AB16: Land | AC16: Yes | AE16: https://www.federalcompass.com/fed-contract-award/W911QY18D0210 | AF16: Other credible third-party source (FPDS-derived task-order history) | AG16: Secondary / aggregator | AH16: Medium | AI16: Distinct committed delivery order W911QY20F0568 shown in the cited task-order history. Parent IDIQ ceiling is not counted as sales. | AJ16: Yes | AK16: No | AL16: No | AM16: No | AN16: No | AO16: Yes | AP16: Included in Land core | AQ16: 0 | AR16: 0 | AS16: 0 | AT16: 0 | AU16: 0 | AV16: 0 | AW16: 1
A17: SM-0013 | B17: SE-FMV-MSN-2020 | C17: 2020-10-22 | D17: 2020 | E17: Sweden | F17: Swedish Defence Materiel Administration (FMV) | G17: Swedish FMV | H17: Army / Land | I17: Saab Barracuda AB | J17: Saab Barracuda | K17: Sweden | L17: UH-2020-256 / Multispektrala Maskeringsnät | M17: Land camouflage / nets | N17: Multispectral camouflage nets | O17: Multispectral | P17: Contract award | Q17: Award | R17: Yes | T17: Unknown | V17: 637392000 | W17: SEK | X17: Final contract value excluding VAT | Y17: Obligated / signed if disclosed | Z17: No | AA17: Production Procurement | AB17: Land | AC17: Yes | AE17: https://www.e-avrop.com/fmv/e-Upphandling/ContractAwardNotice.aspx?id=17759&type=TED | AF17: Official FMV procurement award notice | AG17: Secondary / aggregator | AH17: High | AI17: Major Swedish award absent from the two normalized event datasets. | AJ17: No | AK17: No | AL17: No | AM17: Yes | AN17: No | AO17: Yes | AP17: Included in Land core | AQ17: 0 | AR17: 1 | AS17: 0 | AT17: 0 | AU17: 0 | AV17: 0 | AW17: 0
A18: SM-0014 | B18: ULCANS-IDV-W911QY18D0210 | C18: 2020-11-16 | D18: 2020 | E18: United States | F18: ACC Aberdeen Proving Ground (Natick) / PEO CS&CSS, U.S. Army | G18: U.S. Army | H18: Army / Land | I18: Fibrotex USA Inc. / Fibrotex Technologies | J18: Fibrotex | K18: Israel / USA | L18: W911QY21F0428 — ULCANS delivery order under W911QY18D0210 | M18: Nets / Covers | N18: Ultra-Lightweight Camouflage Net System (ULCANS) | O18: Multispectral | P18: Order | R18: Yes | T18: Unknown | V18: 4800000.0 | W18: USD | Y18: Obligated / signed if disclosed | Z18: Yes | AA18: Production Procurement | AB18: Land | AC18: Yes | AE18: https://www.federalcompass.com/fed-contract-award/W911QY18D0210 | AF18: Other credible third-party source (FPDS-derived task-order history) | AG18: Secondary / aggregator | AH18: Medium | AI18: Distinct committed delivery order W911QY21F0428 shown in the cited task-order history. Parent IDIQ ceiling is not counted as sales. | AJ18: Yes | AK18: No | AL18: No | AM18: No | AN18: No | AO18: Yes | AP18: Included in Land core | AQ18: 0 | AR18: 0 | AS18: 0 | AT18: 0 | AU18: 0 | AV18: 0 | AW18: 1
A19: SM-0015 | B19: AMD-CHAMEM | C19: 2020-12-01 | D19: 2020 | E19: United Kingdom | F19: Dstl Weapons Sector Research Framework | G19: Dstl Weapons Sector Research Framework | H19: Army / Land | I19: Advanced Material Development (AMD) | J19: Advanced Material Development (AMD) | K19: Unknown | L19: ChamEM | M19: Land relevance stated; application detail limited | N19: Radar signature material | O19: Radar / RCS | P19: Funded R&D | Q19: Award | R19: No | T19: Unknown | U19: Unknown | V19: 125000 | W19: GBP | X19: Reported contract value | Y19: Obligated / signed if disclosed | Z19: No | AA19: Development / Validation | AB19: Land | AC19: Yes | AE19: https://www.graphene-info.com/amd-announces-further-contract-extension-us-army | AF19: Industry publication citing company | AG19: Supplier / prime announcement | AH19: Medium | AI19: Public article reports £125k; delivery/platform details are limited. | AJ19: No | AK19: Yes | AL19: No | AM19: No | AN19: No | AO19: Yes | AP19: Included in Land core | AQ19: 1 | AR19: 0 | AS19: 1 | AT19: 1 | AU19: 1 | AV19: 1 | AW19: 0
A20: SM-0016 | B20: ULCANS-IDV-W911QY18D0210 | C20: 2020-12-17 | D20: 2020 | E20: United States | F20: ACC Aberdeen Proving Ground (Natick) / PEO CS&CSS, U.S. Army | G20: U.S. Army | H20: Army / Land | I20: Fibrotex USA Inc. / Fibrotex Technologies | J20: Fibrotex | K20: Israel / USA | L20: W911QY21F0459 — ULCANS delivery order under W911QY18D0210 | M20: Nets / Covers | N20: Ultra-Lightweight Camouflage Net System (ULCANS) | O20: Multispectral | P20: Order | R20: Yes | T20: Unknown | V20: 416700.0 | W20: USD | Y20: Obligated / signed if disclosed | Z20: Yes | AA20: Production Procurement | AB20: Land | AC20: Yes | AE20: https://www.federalcompass.com/fed-contract-award/W911QY18D0210 | AF20: Other credible third-party source (FPDS-derived task-order history) | AG20: Secondary / aggregator | AH20: Medium | AI20: Distinct committed delivery order W911QY21F0459 shown in the cited task-order history. Parent IDIQ ceiling is not counted as sales. | AJ20: Yes | AK20: No | AL20: No | AM20: No | AN20: No | AO20: Yes | AP20: Included in Land core | AQ20: 0 | AR20: 0 | AS20: 0 | AT20: 0 | AU20: 0 | AV20: 0 | AW20: 1
A21: SM-0017 | B21: ULCANS-IDV-W911QY18D0210 | C21: 2020-12-22 | D21: 2020 | E21: United States | F21: ACC Aberdeen Proving Ground / PEO CSCSS, U.S. Army | G21: U.S. Army | H21: Army / Land | I21: Fibrotex USA Inc. / Fibrotex Technologies | J21: Fibrotex | K21: Israel / USA | L21: W911QY21F0100 — Production Units Woodland Type I | M21: Nets / Covers | N21: Ultra-Lightweight Camouflage Net System — Woodland Type I | O21: Multispectral | P21: Order | R21: Yes | T21: Unknown | V21: 10878417.0 | W21: USD | Y21: Obligated / signed if disclosed | Z21: Yes | AA21: Production Procurement | AB21: Land | AC21: Yes | AE21: https://www.nsnlookup.com/cage/7wne0 | AF21: Other credible third-party source (FPDS/USASpending-derived) | AG21: Secondary / aggregator | AH21: High | AI21: Distinct ULCANS delivery order. This row closes a previously missed late-December 2020 order; do not treat later modifications as separate events. | AJ21: Yes | AK21: No | AL21: No | AM21: No | AN21: No | AO21: Yes | AP21: Included in Land core | AQ21: 0 | AR21: 0 | AS21: 0 | AT21: 0 | AU21: 0 | AV21: 0 | AW21: 1
A22: SM-0018 | B22: PL-WISLA-CAMO | C22: 2020-12-30 | D22: 2020 | E22: Poland | F22: Armament Inspectorate (Inspektorat Uzbrojenia), Polish MoD | G22: Polish Armament Agency / predecessor Armament Inspectorate | H22: Defence / not disclosed | I22: Miranda Sp. z o.o. (Lubawa Group) | J22: Miranda Textiles | K22: Poland | L22: WISŁA Phase 1 — Patriot air and missile defence | M22: Nets / Covers | N22: Camouflage and deception systems for WISŁA / Patriot batteries | O22: Not itemised in source | P22: Other | R22: No | T22: Unknown | Y22: Obligated / signed if disclosed | Z22: No | AA22: Other public event | AB22: Land | AC22: Yes | AE22: https://www.dziennikzbrojny.pl/aktualnosci/news%2C1%2C11526%2Caktualnosci-z-polski%2Cumowa-na-system-maskowania-i-pozoracji-w-programie-wisla | AF22: Reputable defence-industry source | AG22: Secondary / aggregator | AH22: High | AI22: Pre-award procurement milestone only. Links to MIR-2021-01 (contract award) and MIR-2022-01 (exercise of the option). Do not count as a commercial sale or add any value. | AJ22: Yes | AK22: No | AL22: No | AM22: No | AN22: No | AO22: Yes | AP22: Included in Land core | AQ22: 1 | AR22: 0 | AS22: 1 | AT22: 1 | AU22: 1 | AV22: 1 | AW22: 0
A23: SM-0019 | B23: ULCANS-IDV-W911QY18D0210 | C23: 2021-03-12 | D23: 2021 | E23: United States | F23: ACC Aberdeen Proving Ground / PEO CSCSS, U.S. Army | G23: U.S. Army | H23: Army / Land | I23: Fibrotex USA Inc. / Fibrotex Technologies | J23: Fibrotex | K23: Israel / USA | L23: W911QY21F0158 — Mobile Camouflage System design/development | M23: Nets / Covers | N23: MCS Preliminary Design Review #3 | O23: Multispectral | P23: Funded Development | R23: No | T23: Unknown | V23: 5500000.0 | W23: USD | Y23: Obligated / signed if disclosed | Z23: No | AA23: Development / Validation | AB23: Land | AC23: Yes | AE23: https://govtribe.com/award/federal-contract-award/other-transaction-agreement-w911qy269a019 | AF23: Other credible third-party source (FPDS/USASpending-derived) | AG23: Secondary / aggregator | AH23: High | AI23: One design/development delivery order under the ULCANS contract family. Public records show later transaction/modification dates; record only the original award event. | AJ23: Yes | AK23: Yes | AL23: No | AM23: No | AN23: No | AO23: Yes | AP23: Included in Land core | AQ23: 1 | AR23: 0 | AS23: 1 | AT23: 1 | AU23: 1 | AV23: 0 | AW23: 0
A24: SM-0020 | B24: ULCANS-IDV-W911QY18D0210 | C24: 2021-05-19 | D24: 2021 | E24: United States | F24: ACC Aberdeen Proving Ground / PEO CSCSS, U.S. Army | G24: U.S. Army | H24: Army / Land | I24: Fibrotex USA Inc. / Fibrotex Technologies | J24: Fibrotex | K24: Israel / USA | L24: W911QY21F0292 — Production Units Woodland Type II | M24: Nets / Covers | N24: ULCANS production units — Woodland Type II | O24: Multispectral | P24: Order | R24: Yes | T24: Unknown | V24: 575215.68 | W24: USD | Y24: Obligated / signed if disclosed | Z24: Yes | AA24: Production Procurement | AB24: Land | AC24: Yes | AE24: https://www.nsnlookup.com/cage/7wne0 | AF24: Other credible third-party source (FPDS/USASpending-derived) | AG24: Secondary / aggregator | AH24: High | AI24: Distinct ULCANS production order. | AJ24: Yes | AK24: No | AL24: No | AM24: No | AN24: No | AO24: Yes | AP24: Included in Land core | AQ24: 0 | AR24: 1 | AS24: 0 | AT24: 0 | AU24: 0 | AV24: 0 | AW24: 1
A25: SM-0021 | B25: AWE-TACTICAM-2021 | C25: 2021-06-07 | D25: 2021 | E25: United States | F25: U.S. Army Natick | G25: U.S. Army | H25: Army / Land | I25: ArmorWorks Enterprises | J25: ArmorWorks Enterprises | K25: Unknown | L25: TactiCam study | M25: Vehicles, buildings and warfighter | N25: TactiCam | O25: VIS/Thermal IR/Radar | P25: Study | Q25: Award | R25: No | T25: Unknown | U25: Unknown | W25: Unknown | X25: Undisclosed | Y25: Obligated / signed if disclosed | Z25: No | AA25: Development / Validation | AB25: Land / Personnel (mixed) | AC25: Yes | AE25: https://www.linkedin.com/posts/armorworks_armorworks-enterprises-inc-announces-a-activity-6809150587029069825-k6NX | AF25: Company social-media post | AG25: Secondary / aggregator | AH25: Low | AI25: Army Natick contracted a study of TactiCam for future warfighter use; supplier evidence states explicit mobile/stationary vehicle and building application. Included as low-confidence land/mixed development evidence, not an order. | AJ25: No | AK25: Yes | AL25: No | AM25: No | AN25: No | AO25: No | AP25: Included in Land core | AQ25: 1 | AR25: 0 | AS25: 1 | AT25: 0 | AU25: 0 | AV25: 1 | AW25: 0
A26: SM-0022 | B26: PL-WISLA-CAMO | C26: 2021-07-08 | D26: 2021 | E26: Poland | F26: Armament Inspectorate (Inspektorat Uzbrojenia), Polish MoD, for the State Treasury | G26: Polish Armament Agency / predecessor Armament Inspectorate | H26: Defence / not disclosed | I26: Miranda Sp. z o.o. (Lubawa Group) | J26: Miranda Textiles | K26: Poland | L26: WISŁA Phase 1 — two Patriot air and missile defence batteries | M26: Nets / Covers | N26: Camouflage and deception systems (systemy maskowania i pozoracji) for Patriot batteries | O26: Not itemised in source | P26: Contract Award | R26: Yes | T26: sets | V26: 36000000.0 | W26: PLN | Y26: Obligated / signed if disclosed | Z26: No | AA26: Production Procurement | AB26: Land | AC26: Yes | AE26: https://www.polska-zbrojna.pl/home/articleshow/34778?t=Polskie-maskowanie-Wisly | AF26: Official military / customer source reported by reputable defence media | AG26: Secondary / aggregator | AH26: High | AI26: The PLN 33m figure was an OPTION at the 2021 award and must not be counted as 2021 sales. The customer subsequently exercised the option in full on 20 Jan 2022; that additional procurement is recorded separately as MIR-2022-01 and should be counted once in 2022. Attributed once to Miranda as consortium leader; Lubawa and WITI are participants and must not be logged as separate events. Head of the PL-WISLA-CAMO procurement chain. | AJ26: Yes | AK26: No | AL26: No | AM26: No | AN26: No | AO26: Yes | AP26: Included in Land core | AQ26: 1 | AR26: 1 | AS26: 1 | AT26: 1 | AU26: 1 | AV26: 0 | AW26: 0
A27: SM-0023 | B27: ULCANS-IDV-W911QY18D0210 | C27: 2021-08-16 | D27: 2021 | E27: United States | F27: ACC Aberdeen Proving Ground / PEO CSCSS, U.S. Army | G27: U.S. Army | H27: Army / Land | I27: Fibrotex USA Inc. / Fibrotex Technologies | J27: Fibrotex | K27: Israel / USA | L27: W911QY21F0399 — LRIP Desert/Urban Type I | M27: Nets / Covers | N27: ULCANS LRIP units — Desert/Urban Type I | O27: Multispectral | P27: Order | R27: Yes | T27: Unknown | V27: 11518669.49 | W27: USD | Y27: Obligated / signed if disclosed | Z27: Yes | AA27: Production Procurement | AB27: Land | AC27: Yes | AE27: https://www.nsnlookup.com/cage/7wne0 | AF27: Other credible third-party source (FPDS/USASpending-derived) | AG27: Secondary / aggregator | AH27: High | AI27: Distinct ULCANS LRIP production order; later transaction dates on the same PIID are not separate events. | AJ27: Yes | AK27: No | AL27: No | AM27: No | AN27: No | AO27: Yes | AP27: Included in Land core | AQ27: 0 | AR27: 0 | AS27: 0 | AT27: 0 | AU27: 0 | AV27: 0 | AW27: 1
A28: SM-0024 | B28: ULCANS-IDV-W911QY18D0210 | C28: 2021-08-20 | D28: 2021 | E28: United States | F28: ACC Aberdeen Proving Ground / PEO CSCSS, U.S. Army | G28: U.S. Army | H28: Army / Land | I28: Fibrotex USA Inc. / Fibrotex Technologies | J28: Fibrotex | K28: Israel / USA | L28: W911QY21F0469 — Field Expedient Camo Kit Class 3 | M28: Nets / Covers | N28: Field Expedient Camouflage Kit Class 3 | O28: Multispectral | P28: Order | R28: Yes | T28: Unknown | V28: 241848.81 | W28: USD | Y28: Obligated / signed if disclosed | Z28: Yes | AA28: Production Procurement | AB28: Land | AC28: Yes | AE28: https://www.nsnlookup.com/cage/7wne0 | AF28: Other credible third-party source (FPDS/USASpending-derived) | AG28: Secondary / aggregator | AH28: High | AI28: Distinct camouflage-kit order under the ULCANS contract family. | AJ28: Yes | AK28: No | AL28: No | AM28: No | AN28: No | AO28: Yes | AP28: Included in Land core | AQ28: 0 | AR28: 0 | AS28: 0 | AT28: 0 | AU28: 0 | AV28: 0 | AW28: 1
A29: SM-0025 | B29: ULCANS-IDV-W911QY18D0210 | C29: 2021-08-24 | D29: 2021 | E29: United States | F29: ACC Aberdeen Proving Ground / PEO CSCSS, U.S. Army | G29: U.S. Army | H29: Army / Land | I29: Fibrotex USA Inc. / Fibrotex Technologies | J29: Fibrotex | K29: Israel / USA | L29: W911QY21F0471 — LRIP Desert/Urban Type I | M29: Nets / Covers | N29: ULCANS LRIP units — Desert/Urban Type I | O29: Multispectral | P29: Order | R29: Yes | T29: Unknown | V29: 16691934.0 | W29: USD | Y29: Obligated / signed if disclosed | Z29: Yes | AA29: Production Procurement | AB29: Land | AC29: Yes | AE29: https://www.nsnlookup.com/cage/7wne0 | AF29: Other credible third-party source (FPDS/USASpending-derived) | AG29: Secondary / aggregator | AH29: High | AI29: Distinct ULCANS LRIP production order; do not count later modifications to this same PIID as new events. | AJ29: Yes | AK29: No | AL29: No | AM29: No | AN29: No | AO29: Yes | AP29: Included in Land core | AQ29: 0 | AR29: 0 | AS29: 0 | AT29: 0 | AU29: 0 | AV29: 0 | AW29: 1
A30: SM-0026 | B30: ULCANS-IDV-W911QY18D0210 | C30: 2021-09-03 | D30: 2021 | E30: United States | F30: ACC Aberdeen Proving Ground / PEO CSCSS, U.S. Army | G30: U.S. Army | H30: Army / Land | I30: Fibrotex USA Inc. / Fibrotex Technologies | J30: Fibrotex | K30: Israel / USA | L30: W911QY21F0490 — Preliminary Design Review | M30: Nets / Covers | N30: Camouflage-system preliminary design review | O30: Multispectral | P30: Funded Development | R30: No | T30: Unknown | V30: 425000.0 | W30: USD | Y30: Obligated / signed if disclosed | Z30: No | AA30: Development / Validation | AB30: Land | AC30: Yes | AE30: https://www.nsnlookup.com/cage/7wne0 | AF30: Other credible third-party source (FPDS/USASpending-derived) | AG30: Secondary / aggregator | AH30: High | AI30: Development milestone under the ULCANS IDIQ. Multiple public transaction dates on the same PIID are consolidated to one event. | AJ30: Yes | AK30: No | AL30: No | AM30: No | AN30: No | AO30: Yes | AP30: Included in Land core | AQ30: 0 | AR30: 0 | AS30: 0 | AT30: 0 | AU30: 0 | AV30: 0 | AW30: 0
A31: SM-0027 | B31: PPG-FA930221D0009 | C31: 2021-09-15 | D31: 2021 | E31: United States | F31: Air Force Test Center / 412th Test Wing, U.S. Air Force | G31: U.S. Air Force | H31: Air Force / Aviation | I31: PPG Industries, Inc. | J31: PPG | K31: USA | L31: FA930221D0009 — Radar Absorbent Material IDIQ | M31: RAM / Composite | N31: Radar Absorbent Material (RAM) | O31: Radar / RCS | P31: Framework / IDIQ | R31: No | T31: Unknown | Y31: Framework / ceiling | Z31: No | AA31: Framework | AB31: Aviation | AC31: No | AD31: Aviation-only | AE31: https://www.federalcompass.com/award-contract-detail/FA930221D0009 | AF31: Other credible third-party source (FPDS-derived) | AG31: Secondary / aggregator | AH31: High | AI31: Framework ceiling only — not actual sales. Actual task-order obligations are recorded separately and must not be added to the ceiling. | AJ31: Yes | AK31: No | AL31: No | AM31: No | AN31: No | AO31: Yes | AP31: Retained as contextual; excluded from Land core | AQ31: 0 | AR31: 0 | AS31: 0 | AT31: 0 | AU31: 0 | AV31: 0 | AW31: 0
A32: SM-0028 | B32: PPG-FA930221D0009 | C32: 2021-09-16 | D32: 2021 | E32: United States | F32: Air Force Test Center / 412th Test Wing, U.S. Air Force | G32: U.S. Air Force | H32: Air Force / Aviation | I32: PPG Industries, Inc. | J32: PPG | K32: USA | L32: FA930221F0115 under FA930221D0009 RAM IDIQ | M32: RAM / Composite | N32: Radar Absorbent Material (RAM) | O32: Radar / RCS | P32: Order | R32: Yes | T32: Unknown | V32: 536900.0 | W32: USD | Y32: Obligated / signed if disclosed | Z32: No | AA32: Production Procurement | AB32: Aviation | AC32: No | AD32: Aviation-only | AE32: https://www.federalcompass.com/award-contract-detail/FA930221D0009 | AF32: Other credible third-party source (FPDS-derived) | AG32: Secondary / aggregator | AH32: High | AI32: Actual task-order obligation. Federal Compass reports the amount rounded to the nearest $0.1k; do not add the parent IDIQ ceiling as sales. | AJ32: Yes | AK32: No | AL32: No | AM32: No | AN32: No | AO32: Yes | AP32: Retained as contextual; excluded from Land core | AQ32: 0 | AR32: 0 | AS32: 0 | AT32: 0 | AU32: 0 | AV32: 0 | AW32: 0
A33: SM-0029 | B33: MAST-N0010421DYW01 | C33: 2021-09-23 | D33: 2021 | E33: United States | F33: NAVSUP Weapon Systems Support, U.S. Navy | G33: U.S. Navy | H33: Navy | I33: MAST Technologies, Inc. | J33: MAST Technologies | K33: USA | L33: N0010421DYW01 — Type 18 rubber tiles for Navy radar/passive countermeasure system | M33: RAM / Composite | N33: Type 18 rubber tiles, NSN 5840-01-464-5293 / part 7338388 | O33: Radar / RCS | P33: Framework / IDIQ | R33: No | S33: 16000 | T33: units | Y33: Framework / ceiling | Z33: No | AA33: Framework | AB33: Maritime | AC33: No | AD33: Maritime/contextual | AE33: https://www.federalcompass.com/award-contract-detail/N0010421DYW01 | AF33: Official/FPDS-derived procurement source plus product/NSN cross-reference | AG33: Secondary / aggregator | AH33: High | AI33: Framework ceiling only; do not count as actual sales. The associated task order is recorded separately. | AJ33: Yes | AK33: No | AL33: No | AM33: No | AN33: No | AO33: Yes | AP33: Retained as contextual; excluded from Land core | AQ33: 0 | AR33: 0 | AS33: 0 | AT33: 0 | AU33: 0 | AV33: 0 | AW33: 0
A34: SM-0030 | B34: MAST-N0010421DYW01 | C34: 2021-09-23 | D34: 2021 | E34: United States | F34: NAVSUP Weapon Systems Support, U.S. Navy | G34: U.S. Navy | H34: Navy | I34: MAST Technologies, Inc. | J34: MAST Technologies | K34: USA | L34: N0010421F0YW0 under N0010421DYW01 | M34: RAM / Composite | N34: Type 18 rubber tiles, NSN 5840-01-464-5293 / passive countermeasure system | O34: Radar / RCS | P34: Order | R34: Yes | T34: Unknown | V34: 5299784.0 | W34: USD | Y34: Obligated / signed if disclosed | Z34: No | AA34: Production Procurement | AB34: Maritime | AC34: No | AD34: Maritime/contextual | AE34: https://www.fpds.gov/ezsearch/fpdsportal?indexName=icdindex&length=186&q=N0010421DYW01 | AF34: Official FPDS / FPDS-derived procurement source | AG34: Secondary / aggregator | AH34: High | AI34: Actual order/obligation; do not add the parent IDIQ ceiling. One commercial transaction linked to the same-day framework award. | AJ34: Yes | AK34: No | AL34: No | AM34: No | AN34: No | AO34: Yes | AP34: Retained as contextual; excluded from Land core | AQ34: 0 | AR34: 0 | AS34: 0 | AT34: 0 | AU34: 0 | AV34: 0 | AW34: 0
A35: SM-0031 | B35: AME-N0017321P0970 | C35: 2021-09-29 | D35: 2021 | E35: United States | F35: Office of Naval Research / Naval Research Laboratory, U.S. Navy | G35: U.S. NRL / ONR | H35: Navy | I35: Ametrine Inc. / Ametrine Technologies | J35: Ametrine Technologies | K35: USA | L35: N0017321P0970 | M35: Nets / Covers | N35: Multispectral Camouflage system | O35: Multispectral | P35: Order | R35: Yes | T35: Unknown | V35: 177000.0 | W35: USD | Y35: Obligated / signed if disclosed | Z35: No | AA35: Production Procurement | AB35: Other / Contextual | AC35: No | AD35: End use / platform not publicly established; NRL/ONR buyer alone does not establish maritime or land domain | AE35: https://govtribe.com/award/federal-contract-award/definitive-contract-n0017325c2461 | AF35: Other credible third-party source (federal procurement record) | AG35: Secondary / aggregator | AH35: High | AI35: Distinct purchase order. A separate older multispectral-mesh PO N0017320P0084 was found but not added because the public snippet did not expose an award date sufficient to prove it fell after 1 Jan 2020. | AJ35: Yes | AK35: Yes | AL35: No | AM35: No | AN35: No | AO35: No | AP35: Retained as contextual; excluded from Land core | AQ35: 0 | AR35: 0 | AS35: 0 | AT35: 0 | AU35: 0 | AV35: 0 | AW35: 0
A36: SM-0032 | B36: PPG-FA930221D0009 | C36: 2021-10-27 | D36: 2021 | E36: United States | F36: Air Force Test Center / 412th Test Wing, U.S. Air Force | G36: U.S. Air Force | H36: Air Force / Aviation | I36: PPG Industries, Inc. | J36: PPG | K36: USA | L36: FA930222F0005 under FA930221D0009 RAM IDIQ | M36: RAM / Composite | N36: Radar Absorbent Material (RAM) | O36: Radar / RCS | P36: Order | R36: Yes | T36: Unknown | V36: 249900.0 | W36: USD | Y36: Obligated / signed if disclosed | Z36: No | AA36: Production Procurement | AB36: Aviation | AC36: No | AD36: Aviation-only | AE36: https://www.federalcompass.com/award-contract-detail/FA930221D0009 | AF36: Other credible third-party source (FPDS-derived) | AG36: Secondary / aggregator | AH36: High | AI36: Actual task-order obligation. Federal Compass reports the amount rounded to the nearest $0.1k; do not add the parent IDIQ ceiling as sales. | AJ36: Yes | AK36: No | AL36: No | AM36: No | AN36: No | AO36: Yes | AP36: Retained as contextual; excluded from Land core | AQ36: 0 | AR36: 0 | AS36: 0 | AT36: 0 | AU36: 0 | AV36: 0 | AW36: 0
A37: SM-0034 | B37: FR-FENRIR | C37: 2022-01-13 | D37: 2022 | E37: France | F37: Direction générale de l'armement (DGA) | G37: French DGA | H37: Defence / not disclosed | I37: Saab AB / Saab Barracuda AB | J37: Saab Barracuda | K37: Sweden | L37: FENRIR — French Army command posts, vehicles, weapons and sensors | M37: Nets / Covers | N37: Barracuda multispectral camouflage systems (framework, incl. system adaptation phase) | O37: Multispectral | P37: Framework / IDIQ | R37: No | T37: Unknown | Y37: Framework / ceiling | Z37: No | AA37: Framework | AB37: Land | AC37: Yes | AE37: https://www.saab.com/newsroom/press-releases/2022/saab-provides-camouflage-systems-to-france | AF37: Official company announcement | AG37: Supplier / prime announcement | AH37: High | AI37: FRAMEWORK ONLY — no value or ceiling disclosed, so nothing to add to order totals. This is the parent of SAA-2024-01 (DGA order, 21 Jan 2024, 3,000 nets, EUR 20m). Count the framework and the order as two milestones and ONE transaction. Also resolves a known date trap: some secondary Saab copy describes a "new DGA contract in early 2023" — that is imprecise phrasing for this Jan 2022 framework and must not be logged as a separate 2023 event. | AJ37: Yes | AK37: No | AL37: No | AM37: No | AN37: No | AO37: Yes | AP37: Included in Land core | AQ37: 1 | AR37: 0 | AS37: 1 | AT37: 1 | AU37: 1 | AV37: 1 | AW37: 0
A38: SM-0035 | B38: PL-WISLA-CAMO | C38: 2022-01-20 | D38: 2022 | E38: Poland | F38: Armament Agency (formerly Armament Inspectorate), Polish MoD | G38: Polish Armament Agency / predecessor Armament Inspectorate | H38: Defence / not disclosed | I38: Miranda Sp. z o.o. (Lubawa Group) | J38: Miranda Textiles | K38: Poland | L38: WISŁA Phase 1 — Patriot air and missile defence | M38: Nets / Covers | N38: Camouflage and deception systems for WISŁA / Patriot batteries | O38: Not itemised in source | P38: Contract Option / Extension | R38: Yes | T38: units | V38: 33266150.0 | W38: PLN | Y38: Obligated / signed if disclosed | Z38: Yes | AA38: Production Procurement | AB38: Land | AC38: Yes | AE38: https://www.money.pl/gielda/komunikaty/6728449260451969.html | AF38: Official company regulatory announcement reported by financial news service | AG38: Primary / official | AH38: High | AI38: This is the exercise of the option that was only a potential/optional amount in MIR-2021-01. For value totals, exclude the 2021 option ceiling and count this 2022 exercised amount once. | AJ38: Yes | AK38: No | AL38: No | AM38: No | AN38: No | AO38: Yes | AP38: Included in Land core | AQ38: 1 | AR38: 1 | AS38: 1 | AT38: 1 | AU38: 1 | AV38: 0 | AW38: 1
A39: SM-0036 | B39: ULCANS-IDV-W911QY18D0210 | C39: 2022-02-28 | D39: 2022 | E39: United States | F39: ACC Aberdeen Proving Ground / PEO CSCSS, U.S. Army | G39: U.S. Army | H39: Army / Land | I39: Fibrotex USA Inc. / Fibrotex Technologies | J39: Fibrotex | K39: Israel / USA | L39: W911QY22F0093 — Desert/Urban Type I | M39: Nets / Covers | N39: ULCANS production system — Desert/Urban Type I | O39: Multispectral | P39: Order | R39: Yes | T39: Unknown | V39: 483013.28 | W39: USD | Y39: Obligated / signed if disclosed | Z39: Yes | AA39: Production Procurement | AB39: Land | AC39: Yes | AE39: https://www.nsnlookup.com/cage/7wne0 | AF39: Other credible third-party source (FPDS/USASpending-derived) | AG39: Secondary / aggregator | AH39: High | AI39: Distinct ULCANS production order. | AJ39: Yes | AK39: Yes | AL39: No | AM39: No | AN39: No | AO39: Yes | AP39: Included in Land core | AQ39: 1 | AR39: 1 | AS39: 1 | AT39: 1 | AU39: 1 | AV39: 0 | AW39: 1
A40: SM-0037 | B40: AU-LAND8116-MCS | C40: 2022-05-13 | D40: 2022 | E40: Australia | F40: Hanwha Defence Australia / Australian Army | G40: Hanwha Defence Australia / Australian Army | H40: Army / Land | I40: CBG Systems | J40: CBG Systems | K40: Unknown | L40: LAND 8116 | M40: AS9 SPH / AS10 AARV | N40: SolarSigmaShield MCS | O40: Multispectral | P40: Production contract | Q40: Production start | R40: Yes | S40: 14 | T40: units | U40: Actual / contracted | W40: Unknown | X40: Undisclosed | Y40: Obligated / signed if disclosed | Z40: No | AA40: Production Procurement | AB40: Land | AC40: Yes | AE40: https://cbgsystems.com/solarsigmashield-mobile-camouflage-systems-partnership-with-hanwha-defense-australia/ | AF40: Company announcement | AG40: Supplier / prime announcement | AH40: Medium | AI40: CBG states it was contracted and manufacture had commenced; 14 platform-specific systems total. | AJ40: No | AK40: Yes | AL40: No | AM40: No | AN40: No | AO40: Yes | AP40: Included in Land core | AQ40: 1 | AR40: 1 | AS40: 1 | AT40: 1 | AU40: 1 | AV40: 1 | AW40: 0
A41: SM-0038 | B41: PPG-FA930221D0009 | C41: 2022-05-19 | D41: 2022 | E41: United States | F41: Air Force Test Center / 412th Test Wing, U.S. Air Force | G41: U.S. Air Force | H41: Air Force / Aviation | I41: PPG Industries, Inc. | J41: PPG | K41: USA | L41: FA930222F0030 under FA930221D0009 RAM IDIQ | M41: RAM / Composite | N41: Radar Absorbent Material (RAM) | O41: Radar / RCS | P41: Order | R41: Yes | T41: Unknown | V41: 353500.0 | W41: USD | Y41: Obligated / signed if disclosed | Z41: No | AA41: Production Procurement | AB41: Aviation | AC41: No | AD41: Aviation-only | AE41: https://www.federalcompass.com/award-contract-detail/FA930221D0009 | AF41: Other credible third-party source (FPDS-derived) | AG41: Secondary / aggregator | AH41: High | AI41: Actual task-order obligation. Federal Compass reports the amount rounded to the nearest $0.1k; do not add the parent IDIQ ceiling as sales. | AJ41: Yes | AK41: No | AL41: No | AM41: No | AN41: No | AO41: Yes | AP41: Retained as contextual; excluded from Land core | AQ41: 0 | AR41: 0 | AS41: 0 | AT41: 0 | AU41: 0 | AV41: 0 | AW41: 0
...

Sheet Programme Families
A1: Final Programme / Procurement Families
A2: 34 land-core families; 45 families across all retained core and contextual evidence. Family IDs follow procurement chains, not publications.
A4: Programme / Procurement Family ID | B4: First Year | C4: Last Year | D4: Country / Countries | E4: Canonical Buyer(s) | F4: Canonical Supplier(s) | G4: Programme / Requirement | H4: Retained Events | I4: Core Events | J4: Actual Orders | K4: Disclosed Actual Quantity | L4: Quantity Unit(s) | M4: Currency / Currencies | N4: Development / Validation Events | O4: Core Family? | P4: Event IDs
A5: AMD-CHAMEM | B5: 2020 | C5: 2022 | D5: United Kingdom; United States | E5: Dstl Weapons Sector Research Framework; U.S. OSD Foreign Comparative Testing | F5: Advanced Material Development (AMD) | G5: ChamEM; ChamEM FCT | H5: 2 | I5: 2 | J5: 0 | N5: 2 | O5: Yes | P5: SM-0015, SM-0042
A6: PL-WISLA-CAMO | B6: 2020 | C6: 2022 | D6: Poland | E6: Polish Armament Agency / predecessor Armament Inspectorate | F6: Miranda Textiles | G6: WISŁA Phase 1 — Patriot air and missile defence; WISŁA Phase 1 — two Patriot air and missile defence batteries | H6: 3 | I6: 3 | J6: 2 | M6: PLN | N6: 0 | O6: Yes | P6: SM-0018, SM-0022, SM-0035
A7: SE-FMV-MSN-2020 | B7: 2020 | C7: 2020 | D7: Sweden | E7: Swedish FMV | F7: Saab Barracuda | G7: UH-2020-256 — Multispektrala Maskeringsnät; UH-2020-256 / Multispektrala Maskeringsnät | H7: 2 | I7: 2 | J7: 1 | M7: SEK | N7: 0 | O7: Yes | P7: SM-0008, SM-0013
A8: ULCANS-IDV-W911QY18D0210 | B8: 2020 | C8: 2026 | D8: United States | E8: Multiple armed forces; U.S. Army | F8: Fibrotex | G8: W911QY20F0114 — ULCANS delivery order under W911QY18D0210; W911QY20F0174 — ULCANS delivery order under W911QY18D0210; W911QY20F0175 — ULCANS delivery order under W911QY18D0210; W911QY20F0273 — ULCANS delivery order under W911QY18D0210; W911QY20F0463 — ULCANS delivery order under W911QY18D0210; W911QY20F0459 — ULCANS delivery order under W911QY18D0210; W911QY20F0514 — ULCANS delivery order under W911QY18D0210; W911QY20F0510 — ULCANS delivery order under W911QY18D0210; W911QY20F0521 — ULCANS delivery order under W911QY18D0210; W911QY20F0568 — ULCANS delivery order under W911QY18D0210; W911QY21F0428 — ULCANS delivery order under W911QY18D0210; W911QY21F0459 — ULCANS delivery order under W911QY18D0210; W911QY21F0100 — Production Units Woodland Type I; W911QY21F0158 — Mobile Camouflage System design/development; W911QY21F0292 — Production Units Woodland Type II; W911QY21F0399 — LRIP Desert/Urban Type I; W911QY21F0469 — Field Expedient Camo Kit Class 3; W911QY21F0471 — LRIP Desert/Urban Type | H8: 39 | I8: 39 | J8: 33 | M8: USD | N8: 5 | O8: Yes | P8: SM-0001, SM-0003, SM-0004, SM-0005, SM-0006, SM-0007, SM-0009, SM-0010, SM-0011, SM-0012, SM-0014, SM-0016, SM-0017, SM-0019, SM-0020, SM-0023, SM-0024, SM-0025, SM-0026, SM-0036, SM-0039, SM-0040, SM-0041, SM-0049, SM-0053, SM-0057, SM-0065, SM-0066, SM-0072, SM-0074, SM-0103, SM-0108, SM-0118, SM-0119, SM-0128, SM-0130, SM-0133, SM-0135, SM-0136
A9: AWE-TACTICAM-2021 | B9: 2021 | C9: 2021 | D9: United States | E9: U.S. Army | F9: ArmorWorks Enterprises | G9: TactiCam study | H9: 1 | I9: 1 | J9: 0 | N9: 1 | O9: Yes | P9: SM-0021
A10: AU-LAND8116-MCS | B10: 2022 | C10: 2026 | D10: Australia | E10: Hanwha Defence Australia / Australian Army | F10: CBG Systems | G10: LAND 8116 | H10: 2 | I10: 2 | J10: 1 | K10: 14 | L10: units | M10: Unknown | N10: 0 | O10: Yes | P10: SM-0037, SM-0127
A11: FR-FENRIR | B11: 2022 | C11: 2024 | D11: France | E11: French DGA | F11: Saab Barracuda | G11: FENRIR — French Army command posts, vehicles, weapons and sensors; FENRIR (Filet écran radar-IR) — French Army and Air & Space Force command posts, vehicles, weapons | H11: 2 | I11: 2 | J11: 1 | K11: 3000 | L11: nets | M11: EUR | N11: 0 | O11: Yes | P11: SM-0034, SM-0058
A12: AME-CNELS-XHANGAR-2023-25 | B12: 2023 | C12: 2025 | D12: United States | E12: U.S. NRL / ONR | F12: Ametrine Technologies | G12: CNELS / field test; X-Hangar / CNELS; X-Hangar test support; Third-generation X-Hangar; N0017325RDH03 — CNELS / third-generation X-Hangar; Camouflage Netting & Expeditionary Lifting Structures / X-Hangar | H12: 6 | I12: 6 | J12: 1 | M12: USD | N12: 3 | O12: Yes | P12: SM-0047, SM-0063, SM-0064, SM-0084, SM-0107, SM-0111
A13: NO-SAAB-MCS-4600002386 | B13: 2023 | C13: 2024 | D13: Norway | E13: Norwegian FMA | F13: Saab Barracuda | G13: Framework 4600002386 / IO 4502428546; P1092; Framework 4600002386 / PO 4502447296; P5049/P5430; Framework 4600002386 / contract 4502439616; P5475-76; Framework 4600002386 / contract 4502510397; P5475-76; Framework 4600002386 / PO 4502549898 | H13: 5 | I13: 5 | J13: 5 | N13: 0 | O13: Yes | P13: SM-0051, SM-0055, SM-0060, SM-0061, SM-0070
A14: PL-BERBERYS-2023 | B14: 2023 | C14: 2023 | D14: Poland | E14: Armament Agency (Agencja Uzbrojenia) / Polish MoD | F14: Miranda Textiles | G14: Polish Armed Forces platform camouflage — BERBERYS | H14: 1 | I14: 1 | J14: 1 | K14: 1000 | L14: covers | M14: PLN | N14: 0 | O14: Yes | P14: SM-0048
A15: SE-FMV-MCS-2023 | B15: 2023 | C15: 2023 | D15: Sweden | E15: Swedish FMV | F15: Saab Barracuda | G15: Object-bound camouflage framework | H15: 1 | I15: 1 | J15: 0 | N15: 0 | O15: Yes | P15: SM-0050
A16: AU-LAND400-P3-MCS | B16: 2024 | C16: 2024 | D16: Australia | E16: Hanwha Defence Australia / Australian Army | F16: CBG Systems | G16: LAND 400 Phase 3 | H16: 1 | I16: 1 | J16: 1 | K16: 129 | L16: units | M16: Unknown | N16: 0 | O16: Yes | P16: SM-0068
A17: BE-SEYNTEX-SIOEN-2024-25 | B17: 2024 | C17: 2025 | D17: Belgium | E17: Belgian Ministry of Defence | F17: Seyntex | G17: Multispectral camouflage nets framework; 24LA102 | H17: 2 | I17: 2 | J17: 0 | N17: 0 | O17: Yes | P17: SM-0076, SM-0115
A18: DE-SMT-2024-25 | B18: 2024 | C18: 2025 | D18: Germany | E18: BAAINBw / Bundeswehr | F18: Sioen Industries | G18: Stationäre multispektrale Tarnausstattung (SMT); Stationäre multispektrale Tarnausstattung (SMT) — initial call-off | H18: 4 | I18: 4 | J18: 1 | M18: EUR | N18: 0 | O18: Yes | P18: SM-0067, SM-0116, SM-0117, SM-0114
A19: DEC-W911NF2490001 | B19: 2024 | C19: 2024 | D19: United States | E19: U.S. Army | F19: DECPT | G19: W911NF2490001 | H19: 1 | I19: 1 | J19: 0 | N19: 1 | O19: Yes | P19: SM-0069
A20: FIB-USAF-FA483024P0076 | B20: 2024 | C20: 2024 | D20: United States | E20: U.S. Air Force / Air Combat Command | F20: Fibrotex | G20: Moody AFB camouflage kits | H20: 1 | I20: 1 | J20: 1 | M20: USD | N20: 0 | O20: Yes | P20: SM-0073
A21: FR-HT4-2024 | B21: 2024 | C21: 2024 | D21: France | E21: French DGA | F21: PGM Précision / Kastinger (HT4) | G21: Prix de l’Audace / AID label | H21: 1 | I21: 1 | J21: 0 | N21: 1 | O21: Yes | P21: SM-0075
A22: JP-MEDS | B22: 2024 | C22: 2026 | D22: Japan | E22: Japan MOD / JGSDF | F22: NAS / Fibrotex programme team | G22: Multiple Electromagnetic Disguise Net Set (MEDS); MEDS / multiple electromagnetic-wave camouflage net; MEDS — Individual camouflage equipment; MEDS — Chemical equipment; MEDS — Communications / electronics equipment; MEDS — Firepower / vehicle equipment; MEDS — Generic equipment set; MEDS — Guided-weapons equipment; MEDS — Medical equipment; MEDS — Verification set; MEDS — Verification sets; MEDS — aviation equipment; MEDS — communications/electronics equipment; MEDS — guided-weapons equipment; MEDS — firepower/vehicle equipment | H22: 24 | I22: 21 | J22: 18 | K22: 3341 | L22: sets | M22: JPY | N22: 2 | O22: Yes | P22: SM-0059, SM-0079, SM-0082, SM-0083, SM-0086, SM-0087, SM-0088, SM-0089, SM-0090, SM-0091, SM-0092, SM-0093, SM-0094, SM-0095, SM-0096, SM-0097, SM-0098, SM-0099, SM-0100, SM-0101, SM-0121, SM-0122, SM-0123, SM-0124
A23: PL-BERBERYS-WB-2024 | B23: 2024 | C23: 2024 | D23: Poland | E23: WB Electronics | F23: Miranda Textiles | G23: BERBERYS multispectral camouflage covers — WB Electronics supply contract | H23: 1 | I23: 1 | J23: 1 | M23: PLN | N23: 0 | O23: Yes | P23: SM-0145
A24: PL-BERBERYS-ZMT-2024 | B24: 2024 | C24: 2024 | D24: Poland | E24: ZM Tarnów / Polish defence supply chain | F24: Miranda Textiles | G24: Berberys 2024–2028 | H24: 1 | I24: 1 | J24: 1 | M24: PLN | N24: 0 | O24: Yes | P24: SM-0062
A25: CH-MSTS-2025 | B25: 2025 | C25: 2025 | D25: Switzerland | E25: armasuisse | F25: SSZ Camouflage Technology; Saab Barracuda | G25: Multispectral camouflage and subterfuge systems; Multispectral Camouflage Systems (MSTS) — invitation procedure (Einladungsverfahren); Multispectral Camouflage Systems (MSTS) | H25: 3 | I25: 3 | J25: 0 | N25: 1 | O25: Yes | P25: SM-0105, SM-0106, SM-0113
A26: DK-SAAB-MCS-IKK | B26: 2025 | C26: 2025 | D26: Denmark | E26: Danish FMI / Army | F26: Saab Barracuda | G26: Danish infantry fighting vehicle camouflage fielding | H26: 1 | I26: 1 | J26: 0 | N26: 0 | O26: Yes | P26: SM-0081
A27: IN-GEM-5756973 | B27: 2025 | C27: 2026 | D27: India | E27: Indian Army / Department of Military Affairs; Indian Ministry of Defence / Department of Military Affairs / Army | F27: Sterlite Camotech | G27: GeM GEM/2024/B/5756973; Army camouflage-net procurement | H27: 2 | I27: 2 | J27: 1 | K27: 1622 | L27: nets | M27: INR | N27: 0 | O27: Yes | P27: SM-0080, SM-0143
A28: PL-MIR-COVERS-2025 | B28: 2025 | C28: 2025 | D28: Poland | E28: Confidential domestic contractor from PGZ Group | F28: Miranda Textiles | G28: Military platform camouflage | H28: 1 | I28: 1 | J28: 1 | M28: PLN | N28: 0 | O28: Yes | P28: SM-0109
A29: FI-ATMIS-GTD26 | B29: 2026 | C29: 2026 | D29: Finland | E29: Griffin Tech Days / defence end users | F29: BCB International | G29: GTD26 | H29: 1 | I29: 1 | J29: 0 | N29: 1 | O29: Yes | P29: SM-0126
A30: LU-BARRACUDA-2026 | B30: 2026 | C30: 2026 | D30: Luxembourg | E30: Luxembourg defence procurement authority | F30: Saab Barracuda | G30: Scania MLST trucks | H30: 1 | I30: 1 | J30: 1 | K30: 32 | L30: sets | M30: EUR | N30: 0 | O30: Yes | P30: SM-0120
A31: NL-SAAB-MCS-2026 | B31: 2026 | C31: 2026 | D31: Netherlands | E31: Netherlands Ministry of Defence | F31: Saab Barracuda | G31: Fennek, PzH2000NL, CV90 and other vehicles; Fennek / Panzerhaubitze | H31: 2 | I31: 2 | J31: 1 | N31: 0 | O31: Yes | P31: SM-0140, SM-0144
A32: NORDIC-SAAB-MCS-2026 | B32: 2026 | C32: 2026 | D32: Nordic joint | E32: Norwegian FMA | F32: Saab Barracuda | G32: Nordic MCS cooperative testing | H32: 1 | I32: 1 | J32: 0 | N32: 1 | O32: Yes | P32: SM-0125
A33: PL-MIR-COVERS-2026 | B33: 2026 | C33: 2026 | D33: Poland | E33: Domestic contractor from PGZ Group | F33: Miranda Textiles | G33: Military platform camouflage | H33: 1 | I33: 1 | J33: 1 | M33: PLN | N33: 0 | O33: Yes | P33: SM-0141
A34: PL-NAREW-CAMO | B34: 2026 | C34: 2026 | D34: Poland | E34: Polish defense prime / state procurement chain | F34: Lubawa | G34: NAREW | H34: 1 | I34: 1 | J34: 0 | N34: 0 | O34: Yes | P34: SM-0138
A35: PL-WISLA-II-CAMO | B35: 2026 | C35: 2026 | D35: Poland | E35: Polish State / Armament Agency | F35: Lubawa | G35: Wisła II | H35: 1 | I35: 1 | J35: 1 | M35: PLN | N35: 0 | O35: Yes | P35: SM-0139
A36: UK-ATMIS-TRIAL-2026 | B36: 2026 | C36: 2026 | D36: United Kingdom | E36: British Army Armoured Cavalry and Engineer units | F36: BCB International | G36: Operational field trials | H36: 1 | I36: 1 | J36: 0 | N36: 1 | O36: Yes | P36: SM-0129
A37: US-AMET-FLINT-MESH-2026 | B37: 2026 | C37: 2026 | D37: United States | E37: U.S. Army | F37: Ametrine Technologies | G37: W912CH26P0033 | H37: 1 | I37: 1 | J37: 1 | M37: USD | N37: 0 | O37: Yes | P37: SM-0131
A38: US-AMET-VEH-MESH-2026 | B38: 2026 | C38: 2026 | D38: United States | E38: U.S. Army | F38: Ametrine Technologies | G38: W912CH26P0031 | H38: 1 | I38: 1 | J38: 1 | M38: USD | N38: 0 | O38: Yes | P38: SM-0132
A39: AMET-MESH-2020 | B39: 2020 | C39: 2020 | D39: United States | E39: U.S. NRL / ONR | F39: Ametrine Technologies | G39: N0017320P0084 | H39: 1 | I39: 0 | J39: 0 | N39: 0 | O39: No | P39: SM-0002
A40: AME-N0017321P0970 | B40: 2021 | C40: 2021 | D40: United States | E40: U.S. NRL / ONR | F40: Ametrine Technologies | G40: N0017321P0970 | H40: 1 | I40: 0 | J40: 0 | N40: 0 | O40: No | P40: SM-0031
A41: MAST-N0010421DYW01 | P41: SM-0029, SM-0030
...

Sheet Annual Metrics
A1: Final Annual Land-Core Metrics — Row-Level Reproduction
A2: All annual counts below are formula-linked to Master Events flags. 2026 covers 1 Jan–9 Sep only.
A4: Year | B4: Total Core Events | C4: Actual Orders | D4: Active Programme / Procurement Families | E4: Programmes with ≥1 Actual Order | F4: Active Suppliers | G4: Unique Canonical Buyers | H4: Countries | I4: Development / Validation Events | J4: Other Commercial Milestones | K4: Order-bearing Families | L4: Largest Family Orders | M4: Largest Family Share
A5: 2020 | B5: =COUNTIFS('Master Events'!$D$5:$D$147,$A5,'Master Events'!$AC$5:$AC$147,"Yes") | C5: =COUNTIFS('Master Events'!$D$5:$D$147,$A5,'Master Events'!$AC$5:$AC$147,"Yes",'Master Events'!$R$5:$R$147,"Yes") | D5: =SUMIFS('Master Events'!$AQ$5:$AQ$147,'Master Events'!$D$5:$D$147,$A5) | E5: =SUMIFS('Master Events'!$AR$5:$AR$147,'Master Events'!$D$5:$D$147,$A5) | F5: =SUMIFS('Master Events'!$AS$5:$AS$147,'Master Events'!$D$5:$D$147,$A5) | G5: =SUMIFS('Master Events'!$AT$5:$AT$147,'Master Events'!$D$5:$D$147,$A5) | H5: =SUMIFS('Master Events'!$AU$5:$AU$147,'Master Events'!$D$5:$D$147,$A5) | I5: =COUNTIFS('Master Events'!$D$5:$D$147,$A5,'Master Events'!$AC$5:$AC$147,"Yes",'Master Events'!$AA$5:$AA$147,"Development / Validation") | J5: =B5-C5-I5 | K5: =E5 | L5: 13 | M5: =IF(C5=0,0,L5/C5)
A6: 2021 | B6: =COUNTIFS('Master Events'!$D$5:$D$147,$A6,'Master Events'!$AC$5:$AC$147,"Yes") | C6: =COUNTIFS('Master Events'!$D$5:$D$147,$A6,'Master Events'!$AC$5:$AC$147,"Yes",'Master Events'!$R$5:$R$147,"Yes") | D6: =SUMIFS('Master Events'!$AQ$5:$AQ$147,'Master Events'!$D$5:$D$147,$A6) | E6: =SUMIFS('Master Events'!$AR$5:$AR$147,'Master Events'!$D$5:$D$147,$A6) | F6: =SUMIFS('Master Events'!$AS$5:$AS$147,'Master Events'!$D$5:$D$147,$A6) | G6: =SUMIFS('Master Events'!$AT$5:$AT$147,'Master Events'!$D$5:$D$147,$A6) | H6: =SUMIFS('Master Events'!$AU$5:$AU$147,'Master Events'!$D$5:$D$147,$A6) | I6: =COUNTIFS('Master Events'!$D$5:$D$147,$A6,'Master Events'!$AC$5:$AC$147,"Yes",'Master Events'!$AA$5:$AA$147,"Development / Validation") | J6: =B6-C6-I6 | K6: =E6 | L6: 4 | M6: =IF(C6=0,0,L6/C6)
A7: 2022 | B7: =COUNTIFS('Master Events'!$D$5:$D$147,$A7,'Master Events'!$AC$5:$AC$147,"Yes") | C7: =COUNTIFS('Master Events'!$D$5:$D$147,$A7,'Master Events'!$AC$5:$AC$147,"Yes",'Master Events'!$R$5:$R$147,"Yes") | D7: =SUMIFS('Master Events'!$AQ$5:$AQ$147,'Master Events'!$D$5:$D$147,$A7) | E7: =SUMIFS('Master Events'!$AR$5:$AR$147,'Master Events'!$D$5:$D$147,$A7) | F7: =SUMIFS('Master Events'!$AS$5:$AS$147,'Master Events'!$D$5:$D$147,$A7) | G7: =SUMIFS('Master Events'!$AT$5:$AT$147,'Master Events'!$D$5:$D$147,$A7) | H7: =SUMIFS('Master Events'!$AU$5:$AU$147,'Master Events'!$D$5:$D$147,$A7) | I7: =COUNTIFS('Master Events'!$D$5:$D$147,$A7,'Master Events'!$AC$5:$AC$147,"Yes",'Master Events'!$AA$5:$AA$147,"Development / Validation") | J7: =B7-C7-I7 | K7: =E7 | L7: 4 | M7: =IF(C7=0,0,L7/C7)
